2021-12-15 18:53:55,839 [ERROR] Internal Server Error: /article
Traceback (most recent call last):
  File "C:\Users\USER\anaconda3\envs\django_youtubetext\lib\site-packages\django\core\handlers\exception.py", line 34, in inner
    response = get_response(request)
  File "C:\Users\USER\anaconda3\envs\django_youtubetext\lib\site-packages\django\core\handlers\base.py", line 115, in _get_response
    response = self.process_exception_by_middleware(e, request)
  File "C:\Users\USER\anaconda3\envs\django_youtubetext\lib\site-packages\django\core\handlers\base.py", line 113, in _get_response
    response = wrapped_callback(request, *callback_args, **callback_kwargs)
  File "C:\Users\USER\anaconda3\envs\django_youtubetext\lib\site-packages\django\views\generic\base.py", line 71, in view
    return self.dispatch(request, *args, **kwargs)
  File "C:\Users\USER\anaconda3\envs\django_youtubetext\lib\site-packages\django\views\generic\base.py", line 97, in dispatch
    return handler(request, *args, **kwargs)
  File "C:\Django\CodeOfLocal\blog\views.py", line 126, in get
    blog = BlogPost.objects.get(pk=blog_pk)
  File "C:\Users\USER\anaconda3\envs\django_youtubetext\lib\site-packages\django\db\models\manager.py", line 82, in manager_method
    return getattr(self.get_queryset(), name)(*args, **kwargs)
  File "C:\Users\USER\anaconda3\envs\django_youtubetext\lib\site-packages\django\db\models\query.py", line 408, in get
    self.model._meta.object_name
blog.models.BlogPost.DoesNotExist: BlogPost matching query does not exist.
2021-12-15 18:53:55,849 [ERROR] "GET /article HTTP/1.1" 500 89761
